Workbook

Sheet Pricing Piso Chile
A1: TABLA DE PRECIOS PISO — CHILE 2026 | AGROVECA GRUPO LATAM
A2: ⚙️ Celda B3 = margen objetivo (recalcula columnas E-K automáticamente). Celda azul = editable. Celda verde = precio propuesto por Gerencia.
A3: MARGEN OBJETIVO → | B3: 0.45 | C3: ← Cambia este % y todo se recalcula
A5: PRODUCTO | B5: FORMATO | C5: COSTO FÁBRICA (PKG) | D5: TAMAÑO FMT | E5: COSTO $/UNIDAD | F5: PRECIO PISO (CALCULADO) | G5: MARGEN CALC % | H5: PRECIO PROM REAL | I5: NUEVO PRECIO PISO PROPUESTO | J5: MARGEN PROPUESTO % | K5: GAP PROP. vs CALC % | L5: VAR $ (Prop - Real) | M5: CLASIF. PROPUESTO | N5: ORDEN FMT
A6: AV ALGAP 30 | B6: 1 L | C6: 3715 | D6: 1 | E6: =C6/D6 -> 3715 | F6: =E6/(1-$B$3) -> 6754.5455 | G6: =$B$3 -> 0.45 | I6: 6800 | J6: =IF(I6="","",(I6-E6)/I6) -> 0.45367647 | K6: =IF(I6="","",(I6-F6)/F6) -> 0.0067294751 | L6: =IF(OR(I6="",H6=""),"",I6-H6) | M6: =IF(I6="","⚪ SIN PROPUESTA",IF(I6<F6*0.95,"🔴 BAJO PISO",IF(I6>F6*1.05,"🟢 SOBRE PISO","🟡 EN PISO"))) -> 🟡 EN PISO | N6: {=IFERROR(_xlfn.SWITCH(B6,"1 L",1,"5 L",2,"5 L (VECA)",2.5,"20 L",3,"200 L",4,"250 GR",5,"500 GR",6,"1000 L",7),99)} -> 1
A7: AV ALGAP 30 | B7: 5 L | C7: 12996 | D7: 5 | E7: =C7/D7 -> 2599.2 | F7: =E7/(1-$B$3) -> 4725.8182 | G7: =$B$3 -> 0.45 | I7: 5000 | J7: =IF(I7="","",(I7-E7)/I7) -> 0.48016 | K7: =IF(I7="","",(I7-F7)/F7) -> 0.058017852 | L7: =IF(OR(I7="",H7=""),"",I7-H7) | M7: =IF(I7="","⚪ SIN PROPUESTA",IF(I7<F7*0.95,"🔴 BAJO PISO",IF(I7>F7*1.05,"🟢 SOBRE PISO","🟡 EN PISO"))) -> 🟢 SOBRE PISO | N7: {=IFERROR(_xlfn.SWITCH(B7,"1 L",1,"5 L",2,"5 L (VECA)",2.5,"20 L",3,"200 L",4,"250 GR",5,"500 GR",6,"1000 L",7),99)} -> 2
A8: AV ALGAP 30 | B8: 20 L | C8: 37644 | D8: 20 | E8: =IF(C8="","",C8/D8) -> 1882.2 | F8: =IF(E8="","",E8/(1-$B$3)) -> 3422.1818 | G8: =$B$3 -> 0.45 | I8: 4000 | J8: =IF(I8="","",(I8-E8)/I8) -> 0.52945 | K8: =IF(I8="","",(I8-F8)/F8) -> 0.16884497 | L8: =IF(OR(I8="",H8=""),"",I8-H8) | M8: =IF(I8="","⚪ SIN PROPUESTA",IF(I8<F8*0.95,"🔴 BAJO PISO",IF(I8>F8*1.05,"🟢 SOBRE PISO","🟡 EN PISO"))) -> 🟢 SOBRE PISO | N8: {=IFERROR(_xlfn.SWITCH(B8,"1 L",1,"5 L",2,"5 L (VECA)",2.5,"20 L",3,"200 L",4,"250 GR",5,"500 GR",6,"1000 L",7),99)} -> 3
A9: AV ALGAP 30 | B9: 200 L | C9: 320130 | D9: 200 | E9: =IF(C9="","",C9/D9) -> 1600.65 | F9: =IF(E9="","",E9/(1-$B$3)) -> 2910.2727 | G9: =$B$3 -> 0.45 | I9: 3500 | J9: =IF(I9="","",(I9-E9)/I9) -> 0.54267143 | K9: =IF(I9="","",(I9-F9)/F9) -> 0.20263643 | L9: =IF(OR(I9="",H9=""),"",I9-H9) | M9: =IF(I9="","⚪ SIN PROPUESTA",IF(I9<F9*0.95,"🔴 BAJO PISO",IF(I9>F9*1.05,"🟢 SOBRE PISO","🟡 EN PISO"))) -> 🟢 SOBRE PISO | N9: {=IFERROR(_xlfn.SWITCH(B9,"1 L",1,"5 L",2,"5 L (VECA)",2.5,"20 L",3,"200 L",4,"250 GR",5,"500 GR",6,"1000 L",7),99)} -> 4
A10: AV ALGAP 30 | B10: 1000 L | C10: 1537520 | D10: 1000 | E10: =IF(C10="","",C10/D10) -> 1537.52 | F10: =IF(E10="","",E10/(1-$B$3)) -> 2795.4909 | G10: =$B$3 -> 0.45 | I10: 3000 | J10: =IF(I10="","",(I10-E10)/I10) -> 0.48749333 | K10: =IF(I10="","",(I10-F10)/F10) -> 0.073156772 | L10: =IF(OR(I10="",H10=""),"",I10-H10) | M10: =IF(I10="","⚪ SIN PROPUESTA",IF(I10<F10*0.95,"🔴 BAJO PISO",IF(I10>F10*1.05,"🟢 SOBRE PISO","🟡 EN PISO"))) -> 🟢 SOBRE PISO | N10: {=IFERROR(_xlfn.SWITCH(B10,"1 L",1,"5 L",2,"5 L (VECA)",2.5,"20 L",3,"200 L",4,"250 GR",5,"500 GR",6,"1000 L",7),99)} -> 7
A11: AV AMIN | B11: 1 L | C11: 3669 | D11: 1 | E11: =C11/D11 -> 3669 | F11: =E11/(1-$B$3) -> 6670.9091 | G11: =$B$3 -> 0.45 | H11: 6602 | I11: 7800 | J11: =IF(I11="","",(I11-E11)/I11) -> 0.52961538 | K11: =IF(I11="","",(I11-F11)/F11) -> 0.16925593 | L11: =IF(OR(I11="",H11=""),"",I11-H11) -> 1198 | M11: =IF(I11="","⚪ SIN PROPUESTA",IF(I11<F11*0.95,"🔴 BAJO PISO",IF(I11>F11*1.05,"🟢 SOBRE PISO","🟡 EN PISO"))) -> 🟢 SOBRE PISO | N11: {=IFERROR(_xlfn.SWITCH(B11,"1 L",1,"5 L",2,"5 L (VECA)",2.5,"20 L",3,"200 L",4,"250 GR",5,"500 GR",6,"1000 L",7),99)} -> 1
A12: AV AMIN | B12: 5 L | C12: 12765 | D12: 5 | E12: =C12/D12 -> 2553 | F12: =E12/(1-$B$3) -> 4641.8182 | G12: =$B$3 -> 0.45 | H12: 7500 | I12: 7000 | J12: =IF(I12="","",(I12-E12)/I12) -> 0.63528571 | K12: =IF(I12="","",(I12-F12)/F12) -> 0.50802977 | L12: =IF(OR(I12="",H12=""),"",I12-H12) -> -500 | M12: =IF(I12="","⚪ SIN PROPUESTA",IF(I12<F12*0.95,"🔴 BAJO PISO",IF(I12>F12*1.05,"🟢 SOBRE PISO","🟡 EN PISO"))) -> 🟢 SOBRE PISO | N12: {=IFERROR(_xlfn.SWITCH(B12,"1 L",1,"5 L",2,"5 L (VECA)",2.5,"20 L",3,"200 L",4,"250 GR",5,"500 GR",6,"1000 L",7),99)} -> 2
A13: AV AMIN | B13: 20 L | C13: 36718 | D13: 20 | E13: =C13/D13 -> 1835.9 | F13: =E13/(1-$B$3) -> 3338 | G13: =$B$3 -> 0.45 | H13: 5008 | I13: 5500 | J13: =IF(I13="","",(I13-E13)/I13) -> 0.6662 | K13: =IF(I13="","",(I13-F13)/F13) -> 0.64769323 | L13: =IF(OR(I13="",H13=""),"",I13-H13) -> 492 | M13: =IF(I13="","⚪ SIN PROPUESTA",IF(I13<F13*0.95,"🔴 BAJO PISO",IF(I13>F13*1.05,"🟢 SOBRE PISO","🟡 EN PISO"))) -> 🟢 SOBRE PISO | N13: {=IFERROR(_xlfn.SWITCH(B13,"1 L",1,"5 L",2,"5 L (VECA)",2.5,"20 L",3,"200 L",4,"250 GR",5,"500 GR",6,"1000 L",7),99)} -> 3
A14: AV AMIN | B14: 200 L | C14: 254381 | D14: 200 | E14: =IF(C14="","",C14/D14) -> 1271.905 | F14: =IF(E14="","",E14/(1-$B$3)) -> 2312.5545 | G14: =$B$3 -> 0.45 | I14: 3500 | J14: =IF(I14="","",(I14-E14)/I14) -> 0.63659857 | K14: =IF(I14="","",(I14-F14)/F14) -> 0.51347781 | L14: =IF(OR(I14="",H14=""),"",I14-H14) | M14: =IF(I14="","⚪ SIN PROPUESTA",IF(I14<F14*0.95,"🔴 BAJO PISO",IF(I14>F14*1.05,"🟢 SOBRE PISO","🟡 EN PISO"))) -> 🟢 SOBRE PISO | N14: {=IFERROR(_xlfn.SWITCH(B14,"1 L",1,"5 L",2,"5 L (VECA)",2.5,"20 L",3,"200 L",4,"250 GR",5,"500 GR",6,"1000 L",7),99)} -> 4
A15: AV AMIN | B15: 1000 L | C15: 1491220 | D15: 1000 | E15: =IF(C15="","",C15/D15) -> 1491.22 | F15: =IF(E15="","",E15/(1-$B$3)) -> 2711.3091 | G15: =$B$3 -> 0.45 | I15: 3000 | J15: =IF(I15="","",(I15-E15)/I15) -> 0.50292667 | K15: =IF(I15="","",(I15-F15)/F15) -> 0.10647658 | L15: =IF(OR(I15="",H15=""),"",I15-H15) | M15: =IF(I15="","⚪ SIN PROPUESTA",IF(I15<F15*0.95,"🔴 BAJO PISO",IF(I15>F15*1.05,"🟢 SOBRE PISO","🟡 EN PISO"))) -> 🟢 SOBRE PISO | N15: {=IFERROR(_xlfn.SWITCH(B15,"1 L",1,"5 L",2,"5 L (VECA)",2.5,"20 L",3,"200 L",4,"250 GR",5,"500 GR",6,"1000 L",7),99)} -> 7
A16: AV AMIN SUGAR | B16: 1 L | C16: 3589 | D16: 1 | E16: =C16/D16 -> 3589 | F16: =E16/(1-$B$3) -> 6525.4545 | G16: =$B$3 -> 0.45 | I16: 9000 | J16: =IF(I16="","",(I16-E16)/I16) -> 0.60122222 | K16: =IF(I16="","",(I16-F16)/F16) -> 0.37921427 | L16: =IF(OR(I16="",H16=""),"",I16-H16) | M16: =IF(I16="","⚪ SIN PROPUESTA",IF(I16<F16*0.95,"🔴 BAJO PISO",IF(I16>F16*1.05,"🟢 SOBRE PISO","🟡 EN PISO"))) -> 🟢 SOBRE PISO | N16: {=IFERROR(_xlfn.SWITCH(B16,"1 L",1,"5 L",2,"5 L (VECA)",2.5,"20 L",3,"200 L",4,"250 GR",5,"500 GR",6,"1000 L",7),99)} -> 1
A17: AV AMIN SUGAR | B17: 5 L | C17: 12367 | D17: 5 | E17: =C17/D17 -> 2473.4 | F17: =E17/(1-$B$3) -> 4497.0909 | G17: =$B$3 -> 0.45 | H17: 6004 | I17: 8000 | J17: =IF(I17="","",(I17-E17)/I17) -> 0.690825 | K17: =IF(I17="","",(I17-F17)/F17) -> 0.77892779 | L17: =IF(OR(I17="",H17=""),"",I17-H17) -> 1996 | M17: =IF(I17="","⚪ SIN PROPUESTA",IF(I17<F17*0.95,"🔴 BAJO PISO",IF(I17>F17*1.05,"🟢 SOBRE PISO","🟡 EN PISO"))) -> 🟢 SOBRE PISO | N17: {=IFERROR(_xlfn.SWITCH(B17,"1 L",1,"5 L",2,"5 L (VECA)",2.5,"20 L",3,"200 L",4,"250 GR",5,"500 GR",6,"1000 L",7),99)} -> 2
A18: AV AMIN SUGAR | B18: 20 L | C18: 35129 | D18: 20 | E18: =C18/D18 -> 1756.45 | F18: =E18/(1-$B$3) -> 3193.5455 | G18: =$B$3 -> 0.45 | H18: 5375 | I18: 6500 | J18: =IF(I18="","",(I18-E18)/I18) -> 0.72977692 | K18: =IF(I18="","",(I18-F18)/F18) -> 1.0353554 | L18: =IF(OR(I18="",H18=""),"",I18-H18) -> 1125 | M18: =IF(I18="","⚪ SIN PROPUESTA",IF(I18<F18*0.95,"🔴 BAJO PISO",IF(I18>F18*1.05,"🟢 SOBRE PISO","🟡 EN PISO"))) -> 🟢 SOBRE PISO | N18: {=IFERROR(_xlfn.SWITCH(B18,"1 L",1,"5 L",2,"5 L (VECA)",2.5,"20 L",3,"200 L",4,"250 GR",5,"500 GR",6,"1000 L",7),99)} -> 3
A19: AV AMIN SUGAR | B19: 200 L | C19: 238491 | D19: 200 | E19: =IF(C19="","",C19/D19) -> 1192.455 | F19: =IF(E19="","",E19/(1-$B$3)) -> 2168.1 | G19: =$B$3 -> 0.45 | H19: 4500 | I19: 5000 | J19: =IF(I19="","",(I19-E19)/I19) -> 0.761509 | K19: =IF(I19="","",(I19-F19)/F19) -> 1.3061667 | L19: =IF(OR(I19="",H19=""),"",I19-H19) -> 500 | M19: =IF(I19="","⚪ SIN PROPUESTA",IF(I19<F19*0.95,"🔴 BAJO PISO",IF(I19>F19*1.05,"🟢 SOBRE PISO","🟡 EN PISO"))) -> 🟢 SOBRE PISO | N19: {=IFERROR(_xlfn.SWITCH(B19,"1 L",1,"5 L",2,"5 L (VECA)",2.5,"20 L",3,"200 L",4,"250 GR",5,"500 GR",6,"1000 L",7),99)} -> 4
A20: AV AMIN SUGAR | B20: 1000 L | C20: 1411770 | D20: 1000 | E20: =IF(C20="","",C20/D20) -> 1411.77 | F20: =IF(E20="","",E20/(1-$B$3)) -> 2566.8545 | G20: =$B$3 -> 0.45 | I20: 4000 | J20: =IF(I20="","",(I20-E20)/I20) -> 0.6470575 | K20: =IF(I20="","",(I20-F20)/F20) -> 0.55832749 | L20: =IF(OR(I20="",H20=""),"",I20-H20) | M20: =IF(I20="","⚪ SIN PROPUESTA",IF(I20<F20*0.95,"🔴 BAJO PISO",IF(I20>F20*1.05,"🟢 SOBRE PISO","🟡 EN PISO"))) -> 🟢 SOBRE PISO | N20: {=IFERROR(_xlfn.SWITCH(B20,"1 L",1,"5 L",2,"5 L (VECA)",2.5,"20 L",3,"200 L",4,"250 GR",5,"500 GR",6,"1000 L",7),99)} -> 7
A21: AV BALANCE | B21: 1 L | C21: 4631 | D21: 1 | E21: =C21/D21 -> 4631 | F21: =E21/(1-$B$3) -> 8420 | G21: =$B$3 -> 0.45 | H21: 13661 | I21: 15000 | J21: =IF(I21="","",(I21-E21)/I21) -> 0.69126667 | K21: =IF(I21="","",(I21-F21)/F21) -> 0.78147268 | L21: =IF(OR(I21="",H21=""),"",I21-H21) -> 1339 | M21: =IF(I21="","⚪ SIN PROPUESTA",IF(I21<F21*0.95,"🔴 BAJO PISO",IF(I21>F21*1.05,"🟢 SOBRE PISO","🟡 EN PISO"))) -> 🟢 SOBRE PISO | N21: {=IFERROR(_xlfn.SWITCH(B21,"1 L",1,"5 L",2,"5 L (VECA)",2.5,"20 L",3,"200 L",4,"250 GR",5,"500 GR",6,"1000 L",7),99)} -> 1
A22: AV BALANCE | B22: 5 L | C22: 17574 | D22: 5 | E22: =C22/D22 -> 3514.8 | F22: =E22/(1-$B$3) -> 6390.5455 | G22: =$B$3 -> 0.45 | H22: 14239 | I22: 14000 | J22: =IF(I22="","",(I22-E22)/I22) -> 0.74894286 | K22: =IF(I22="","",(I22-F22)/F22) -> 1.1907363 | L22: =IF(OR(I22="",H22=""),"",I22-H22) -> -239 | M22: =IF(I22="","⚪ SIN PROPUESTA",IF(I22<F22*0.95,"🔴 BAJO PISO",IF(I22>F22*1.05,"🟢 SOBRE PISO","🟡 EN PISO"))) -> 🟢 SOBRE PISO | N22: {=IFERROR(_xlfn.SWITCH(B22,"1 L",1,"5 L",2,"5 L (VECA)",2.5,"20 L",3,"200 L",4,"250 GR",5,"500 GR",6,"1000 L",7),99)} -> 2
A23: AV BALANCE | B23: 20 L | C23: 55955 | D23: 20 | E23: =C23/D23 -> 2797.75 | F23: =E23/(1-$B$3) -> 5086.8182 | G23: =$B$3 -> 0.45 | H23: 13691 | I23: 13500 | J23: =IF(I23="","",(I23-E23)/I23) -> 0.79275926 | K23: =IF(I23="","",(I23-F23)/F23) -> 1.6539183 | L23: =IF(OR(I23="",H23=""),"",I23-H23) -> -191 | M23: =IF(I23="","⚪ SIN PROPUESTA",IF(I23<F23*0.95,"🔴 BAJO PISO",IF(I23>F23*1.05,"🟢 SOBRE PISO","🟡 EN PISO"))) -> 🟢 SOBRE PISO | N23: {=IFERROR(_xlfn.SWITCH(B23,"1 L",1,"5 L",2,"5 L (VECA)",2.5,"20 L",3,"200 L",4,"250 GR",5,"500 GR",6,"1000 L",7),99)} -> 3
A24: AV BALANCE | B24: 200 L | C24: 503237 | D24: 200 | E24: =IF(C24="","",C24/D24) -> 2516.185 | F24: =IF(E24="","",E24/(1-$B$3)) -> 4574.8818 | G24: =$B$3 -> 0.45 | I24: 11000 | J24: =IF(I24="","",(I24-E24)/I24) -> 0.77125591 | K24: =IF(I24="","",(I24-F24)/F24) -> 1.4044337 | L24: =IF(OR(I24="",H24=""),"",I24-H24) | M24: =IF(I24="","⚪ SIN PROPUESTA",IF(I24<F24*0.95,"🔴 BAJO PISO",IF(I24>F24*1.05,"🟢 SOBRE PISO","🟡 EN PISO"))) -> 🟢 SOBRE PISO | N24: {=IFERROR(_xlfn.SWITCH(B24,"1 L",1,"5 L",2,"5 L (VECA)",2.5,"20 L",3,"200 L",4,"250 GR",5,"500 GR",6,"1000 L",7),99)} -> 4
A25: AV BALANCE | B25: 1000 L | C25: 2453056 | D25: 1000 | E25: =IF(C25="","",C25/D25) -> 2453.056 | F25: =IF(E25="","",E25/(1-$B$3)) -> 4460.1018 | G25: =$B$3 -> 0.45 | I25: 10000 | J25: =IF(I25="","",(I25-E25)/I25) -> 0.7546944 | K25: =IF(I25="","",(I25-F25)/F25) -> 1.2421013 | L25: =IF(OR(I25="",H25=""),"",I25-H25) | M25: =IF(I25="","⚪ SIN PROPUESTA",IF(I25<F25*0.95,"🔴 BAJO PISO",IF(I25>F25*1.05,"🟢 SOBRE PISO","🟡 EN PISO"))) -> 🟢 SOBRE PISO | N25: {=IFERROR(_xlfn.SWITCH(B25,"1 L",1,"5 L",2,"5 L (VECA)",2.5,"20 L",3,"200 L",4,"250 GR",5,"500 GR",6,"1000 L",7),99)} -> 7
A26: AV BIOSOLARIS | B26: 1 L | C26: 4143 | D26: 1 | E26: =C26/D26 -> 4143 | F26: =E26/(1-$B$3) -> 7532.7273 | G26: =$B$3 -> 0.45 | H26: 12757 | I26: 16000 | J26: =IF(I26="","",(I26-E26)/I26) -> 0.7410625 | K26: =IF(I26="","",(I26-F26)/F26) -> 1.1240647 | L26: =IF(OR(I26="",H26=""),"",I26-H26) -> 3243 | M26: =IF(I26="","⚪ SIN PROPUESTA",IF(I26<F26*0.95,"🔴 BAJO PISO",IF(I26>F26*1.05,"🟢 SOBRE PISO","🟡 EN PISO"))) -> 🟢 SOBRE PISO | N26: {=IFERROR(_xlfn.SWITCH(B26,"1 L",1,"5 L",2,"5 L (VECA)",2.5,"20 L",3,"200 L",4,"250 GR",5,"500 GR",6,"1000 L",7),99)} -> 1
A27: AV BIOSOLARIS | B27: 5 L | C27: 15134 | D27: 5 | E27: =C27/D27 -> 3026.8 | F27: =E27/(1-$B$3) -> 5503.2727 | G27: =$B$3 -> 0.45 | I27: 15000 | J27: =IF(I27="","",(I27-E27)/I27) -> 0.79821333 | K27: =IF(I27="","",(I27-F27)/F27) -> 1.7256509 | L27: =IF(OR(I27="",H27=""),"",I27-H27) | M27: =IF(I27="","⚪ SIN PROPUESTA",IF(I27<F27*0.95,"🔴 BAJO PISO",IF(I27>F27*1.05,"🟢 SOBRE PISO","🟡 EN PISO"))) -> 🟢 SOBRE PISO | N27: {=IFERROR(_xlfn.SWITCH(B27,"1 L",1,"5 L",2,"5 L (VECA)",2.5,"20 L",3,"200 L",4,"250 GR",5,"500 GR",6,"1000 L",7),99)} -> 2
A28: AV BIOSOLARIS | B28: 20 L | C28: 46195 | D28: 20 | E28: =C28/D28 -> 2309.75 | F28: =E28/(1-$B$3) -> 4199.5455 | G28: =$B$3 -> 0.45 | H28: 14250 | I28: 14000 | J28: =IF(I28="","",(I28-E28)/I28) -> 0.83501786 | K28: =IF(I28="","",(I28-F28)/F28) -> 2.3336941 | L28: =IF(OR(I28="",H28=""),"",I28-H28) -> -250 | M28: =IF(I28="","⚪ SIN PROPUESTA",IF(I28<F28*0.95,"🔴 BAJO PISO",IF(I28>F28*1.05,"🟢 SOBRE PISO","🟡 EN PISO"))) -> 🟢 SOBRE PISO | N28: {=IFERROR(_xlfn.SWITCH(B28,"1 L",1,"5 L",2,"5 L (VECA)",2.5,"20 L",3,"200 L",4,"250 GR",5,"500 GR",6,"1000 L",7),99)} -> 3
A29: AV BIOSOLARIS | B29: 200 L | C29: 405640 | D29: 200 | E29: =IF(C29="","",C29/D29) -> 2028.2 | F29: =IF(E29="","",E29/(1-$B$3)) -> 3687.6364 | G29: =$B$3 -> 0.45 | I29: 13000 | J29: =IF(I29="","",(I29-E29)/I29) -> 0.84398462 | K29: =IF(I29="","",(I29-F29)/F29) -> 2.5252934 | L29: =IF(OR(I29="",H29=""),"",I29-H29) | M29: =IF(I29="","⚪ SIN PROPUESTA",IF(I29<F29*0.95,"🔴 BAJO PISO",IF(I29>F29*1.05,"🟢 SOBRE PISO","🟡 EN PISO"))) -> 🟢 SOBRE PISO | N29: {=IFERROR(_xlfn.SWITCH(B29,"1 L",1,"5 L",2,"5 L (VECA)",2.5,"20 L",3,"200 L",4,"250 GR",5,"500 GR",6,"1000 L",7),99)} -> 4
A30: AV BIOSOLARIS | B30: 1000 L | C30: 1965071 | D30: 1000 | E30: =IF(C30="","",C30/D30) -> 1965.071 | F30: =IF(E30="","",E30/(1-$B$3)) -> 3572.8564 | G30: =$B$3 -> 0.45 | I30: 10000 | J30: =IF(I30="","",(I30-E30)/I30) -> 0.8034929 | K30: =IF(I30="","",(I30-F30)/F30) -> 1.7988811 | L30: =IF(OR(I30="",H30=""),"",I30-H30) | M30: =IF(I30="","⚪ SIN PROPUESTA",IF(I30<F30*0.95,"🔴 BAJO PISO",IF(I30>F30*1.05,"🟢 SOBRE PISO","🟡 EN PISO"))) -> 🟢 SOBRE PISO | N30: {=IFERROR(_xlfn.SWITCH(B30,"1 L",1,"5 L",2,"5 L (VECA)",2.5,"20 L",3,"200 L",4,"250 GR",5,"500 GR",6,"1000 L",7),99)} -> 7
A31: AV BLOOM | B31: 1 L | C31: 4096 | D31: 1 | E31: =C31/D31 -> 4096 | F31: =E31/(1-$B$3) -> 7447.2727 | G31: =$B$3 -> 0.45 | H31: 9912 | I31: 11000 | J31: =IF(I31="","",(I31-E31)/I31) -> 0.62763636 | K31: =IF(I31="","",(I31-F31)/F31) -> 0.47705078 | L31: =IF(OR(I31="",H31=""),"",I31-H31) -> 1088 | M31: =IF(I31="","⚪ SIN PROPUESTA",IF(I31<F31*0.95,"🔴 BAJO PISO",IF(I31>F31*1.05,"🟢 SOBRE PISO","🟡 EN PISO"))) -> 🟢 SOBRE PISO | N31: {=IFERROR(_xlfn.SWITCH(B31,"1 L",1,"5 L",2,"5 L (VECA)",2.5,"20 L",3,"200 L",4,"250 GR",5,"500 GR",6,"1000 L",7),99)} -> 1
A32: AV BLOOM | B32: 5 L | C32: 14901 | D32: 5 | E32: =C32/D32 -> 2980.2 | F32: =E32/(1-$B$3) -> 5418.5455 | G32: =$B$3 -> 0.45 | H32: 8548 | I32: 9500 | J32: =IF(I32="","",(I32-E32)/I32) -> 0.68629474 | K32: =IF(I32="","",(I32-F32)/F32) -> 0.75323804 | L32: =IF(OR(I32="",H32=""),"",I32-H32) -> 952 | M32: =IF(I32="","⚪ SIN PROPUESTA",IF(I32<F32*0.95,"🔴 BAJO PISO",IF(I32>F32*1.05,"🟢 SOBRE PISO","🟡 EN PISO"))) -> 🟢 SOBRE PISO | N32: {=IFERROR(_xlfn.SWITCH(B32,"1 L",1,"5 L",2,"5 L (VECA)",2.5,"20 L",3,"200 L",4,"250 GR",5,"500 GR",6,"1000 L",7),99)} -> 2
A33: AV BLOOM | B33: 20 L | C33: 45266 | D33: 20 | E33: =C33/D33 -> 2263.3 | F33: =E33/(1-$B$3) -> 4115.0909 | G33: =$B$3 -> 0.45 | H33: 9300 | I33: 9000 | J33: =IF(I33="","",(I33-E33)/I33) -> 0.74852222 | K33: =IF(I33="","",(I33-F33)/F33) -> 1.187072 | L33: =IF(OR(I33="",H33=""),"",I33-H33) -> -300 | M33: =IF(I33="","⚪ SIN PROPUESTA",IF(I33<F33*0.95,"🔴 BAJO PISO",IF(I33>F33*1.05,"🟢 SOBRE PISO","🟡 EN PISO"))) -> 🟢 SOBRE PISO | N33: {=IFERROR(_xlfn.SWITCH(B33,"1 L",1,"5 L",2,"5 L (VECA)",2.5,"20 L",3,"200 L",4,"250 GR",5,"500 GR",6,"1000 L",7),99)} -> 3
A34: AV BLOOM | B34: 200 L | C34: 396347 | D34: 200 | E34: =IF(C34="","",C34/D34) -> 1981.735 | F34: =IF(E34="","",E34/(1-$B$3)) -> 3603.1545 | G34: =$B$3 -> 0.45 | I34: 8000 | J34: =IF(I34="","",(I34-E34)/I34) -> 0.75228313 | K34: =IF(I34="","",(I34-F34)/F34) -> 1.2202767 | L34: =IF(OR(I34="",H34=""),"",I34-H34) | M34: =IF(I34="","⚪ SIN PROPUESTA",IF(I34<F34*0.95,"🔴 BAJO PISO",IF(I34>F34*1.05,"🟢 SOBRE PISO","🟡 EN PISO"))) -> 🟢 SOBRE PISO | N34: {=IFERROR(_xlfn.SWITCH(B34,"1 L",1,"5 L",2,"5 L (VECA)",2.5,"20 L",3,"200 L",4,"250 GR",5,"500 GR",6,"1000 L",7),99)} -> 4
A35: AV BLOOM | B35: 1000 L | C35: 1918607 | D35: 1000 | E35: =IF(C35="","",C35/D35) -> 1918.607 | F35: =IF(E35="","",E35/(1-$B$3)) -> 3488.3764 | G35: =$B$3 -> 0.45 | I35: 7000 | J35: =IF(I35="","",(I35-E35)/I35) -> 0.72591329 | K35: =IF(I35="","",(I35-F35)/F35) -> 1.0066642 | L35: =IF(OR(I35="",H35=""),"",I35-H35) | M35: =IF(I35="","⚪ SIN PROPUESTA",IF(I35<F35*0.95,"🔴 BAJO PISO",IF(I35>F35*1.05,"🟢 SOBRE PISO","🟡 EN PISO"))) -> 🟢 SOBRE PISO | N35: {=IFERROR(_xlfn.SWITCH(B35,"1 L",1,"5 L",2,"5 L (VECA)",2.5,"20 L",3,"200 L",4,"250 GR",5,"500 GR",6,"1000 L",7),99)} -> 7
A36: AV CYTO PRIME | B36: 1 L | C36: 4500 | D36: 1 | E36: =C36/D36 -> 4500 | F36: =E36/(1-$B$3) -> 8181.8182 | G36: =$B$3 -> 0.45 | I36: 18000 | J36: =IF(I36="","",(I36-E36)/I36) -> 0.75 | K36: =IF(I36="","",(I36-F36)/F36) -> 1.2 | L36: =IF(OR(I36="",H36=""),"",I36-H36) | M36: =IF(I36="","⚪ SIN PROPUESTA",IF(I36<F36*0.95,"🔴 BAJO PISO",IF(I36>F36*1.05,"🟢 SOBRE PISO","🟡 EN PISO"))) -> 🟢 SOBRE PISO | N36: {=IFERROR(_xlfn.SWITCH(B36,"1 L",1,"5 L",2,"5 L (VECA)",2.5,"20 L",3,"200 L",4,"250 GR",5,"500 GR",6,"1000 L",7),99)} -> 1
A37: AV CYTO PRIME | B37: 5 L | C37: 16920 | D37: 5 | E37: =C37/D37 -> 3384 | F37: =E37/(1-$B$3) -> 6152.7273 | G37: =$B$3 -> 0.45 | H37: 16911 | I37: 17000 | J37: =IF(I37="","",(I37-E37)/I37) -> 0.80094118 | K37: =IF(I37="","",(I37-F37)/F37) -> 1.7630024 | L37: =IF(OR(I37="",H37=""),"",I37-H37) -> 89 | M37: =IF(I37="","⚪ SIN PROPUESTA",IF(I37<F37*0.95,"🔴 BAJO PISO",IF(I37>F37*1.05,"🟢 SOBRE PISO","🟡 EN PISO"))) -> 🟢 SOBRE PISO | N37: {=IFERROR(_xlfn.SWITCH(B37,"1 L",1,"5 L",2,"5 L (VECA)",2.5,"20 L",3,"200 L",4,"250 GR",5,"500 GR",6,"1000 L",7),99)} -> 2
A38: AV CYTO PRIME | B38: 20 L | C38: 53340 | D38: 20 | E38: =IF(C38="","",C38/D38) -> 2667 | F38: =IF(E38="","",E38/(1-$B$3)) -> 4849.0909 | G38: =$B$3 -> 0.45 | H38: 16000 | I38: 15800 | J38: =IF(I38="","",(I38-E38)/I38) -> 0.83120253 | K38: =IF(I38="","",(I38-F38)/F38) -> 2.2583427 | L38: =IF(OR(I38="",H38=""),"",I38-H38) -> -200 | M38: =IF(I38="","⚪ SIN PROPUESTA",IF(I38<F38*0.95,"🔴 BAJO PISO",IF(I38>F38*1.05,"🟢 SOBRE PISO","🟡 EN PISO"))) -> 🟢 SOBRE PISO | N38: {=IFERROR(_xlfn.SWITCH(B38,"1 L",1,"5 L",2,"5 L (VECA)",2.5,"20 L",3,"200 L",4,"250 GR",5,"500 GR",6,"1000 L",7),99)} -> 3
A39: AV CYTO PRIME | B39: 200 L | C39: 477086 | D39: 200 | E39: =IF(C39="","",C39/D39) -> 2385.43 | F39: =IF(E39="","",E39/(1-$B$3)) -> 4337.1455 | G39: =$B$3 -> 0.45 | I39: 14000 | J39: =IF(I39="","",(I39-E39)/I39) -> 0.82961214 | K39: =IF(I39="","",(I39-F39)/F39) -> 2.2279296 | L39: =IF(OR(I39="",H39=""),"",I39-H39) | M39: =IF(I39="","⚪ SIN PROPUESTA",IF(I39<F39*0.95,"🔴 BAJO PISO",IF(I39>F39*1.05,"🟢 SOBRE PISO","🟡 EN PISO"))) -> 🟢 SOBRE PISO | N39: {=IFERROR(_xlfn.SWITCH(B39,"1 L",1,"5 L",2,"5 L (VECA)",2.5,"20 L",3,"200 L",4,"250 GR",5,"500 GR",6,"1000 L",7),99)} -> 4
A40: AV CYTO PRIME | B40: 1000 L | C40: 2322301 | D40: 1000 | E40: =IF(C40="","",C40/D40) -> 2322.301 | F40: =IF(E40="","",E40/(1-$B$3)) -> 4222.3655 | G40: =$B$3 -> 0.45 | I40: 11000 | J40: =IF(I40="","",(I40-E40)/I40) -> 0.78888173 | K40: =IF(I40="","",(I40-F40)/F40) -> 1.6051748 | L40: =IF(OR(I40="",H40=""),"",I40-H40) | M40: =IF(I40="","⚪ SIN PROPUESTA",IF(I40<F40*0.95,"🔴 BAJO PISO",IF(I40>F40*1.05,"🟢 SOBRE PISO","🟡 EN PISO"))) -> 🟢 SOBRE PISO | N40: {=IFERROR(_xlfn.SWITCH(B40,"1 L",1,"5 L",2,"5 L (VECA)",2.5,"20 L",3,"200 L",4,"250 GR",5,"500 GR",6,"1000 L",7),99)} -> 7
A41: AV HUMIC ROOT | B41: 1 L | C41: 3338 | D41: 1 | E41: =C41/D41 -> 3338 | F41: =E41/(1-$B$3) -> 6069.0909 | G41: =$B$3 -> 0.45 | I41: 6500 | J41: =IF(I41="","",(I41-E41)/I41) -> 0.48646154 | K41: =IF(I41="","",(I41-F41)/F41) -> 0.071000599 | L41: =IF(OR(I41="",H41=""),"",I41-H41) | M41: =IF(I41="","⚪ SIN PROPUESTA",IF(I41<F41*0.95,"🔴 BAJO PISO",IF(I41>F41*1.05,"🟢 SOBRE PISO","🟡 EN PISO"))) -> 🟢 SOBRE PISO | N41: {=IFERROR(_xlfn.SWITCH(B41,"1 L",1,"5 L",2,"5 L (VECA)",2.5,"20 L",3,"200 L",4,"250 GR",5,"500 GR",6,"1000 L",7),99)} -> 1
...

Sheet Lista de precios
B1: LISTA DE PRECIOS PISO — FUERZA COMERCIAL CHILE 2026
B2: AGROVECA GRUPO LATAM | Precios mínimos de venta | Vigencia: Abril 2026 | Aprobado: Gerencia General
B3: ⚠️ Ninguna venta puede realizarse por debajo de estos precios sin autorización escrita de Gerencia General.
B4: PRODUCTO | C4: FORMATO | D4: Precio Piso AV
B5: ='Pricing Piso Chile'!A6 -> AV ALGAP 30 | C5: ='Pricing Piso Chile'!B6 -> 1 L | D5: ='Pricing Piso Chile'!I6 -> 6800
B6: ='Pricing Piso Chile'!A7 -> AV ALGAP 30 | C6: ='Pricing Piso Chile'!B7 -> 5 L | D6: ='Pricing Piso Chile'!I7 -> 5000
B7: ='Pricing Piso Chile'!A8 -> AV ALGAP 30 | C7: ='Pricing Piso Chile'!B8 -> 20 L | D7: ='Pricing Piso Chile'!I8 -> 4000
B8: ='Pricing Piso Chile'!A9 -> AV ALGAP 30 | C8: ='Pricing Piso Chile'!B9 -> 200 L | D8: ='Pricing Piso Chile'!I9 -> 3500
B9: ='Pricing Piso Chile'!A10 -> AV ALGAP 30 | C9: ='Pricing Piso Chile'!B10 -> 1000 L | D9: ='Pricing Piso Chile'!I10 -> 3000
B10: ='Pricing Piso Chile'!A11 -> AV AMIN | C10: ='Pricing Piso Chile'!B11 -> 1 L | D10: ='Pricing Piso Chile'!I11 -> 7800
B11: ='Pricing Piso Chile'!A12 -> AV AMIN | C11: ='Pricing Piso Chile'!B12 -> 5 L | D11: ='Pricing Piso Chile'!I12 -> 7000
B12: ='Pricing Piso Chile'!A13 -> AV AMIN | C12: ='Pricing Piso Chile'!B13 -> 20 L | D12: ='Pricing Piso Chile'!I13 -> 5500
B13: ='Pricing Piso Chile'!A14 -> AV AMIN | C13: ='Pricing Piso Chile'!B14 -> 200 L | D13: ='Pricing Piso Chile'!I14 -> 3500
B14: ='Pricing Piso Chile'!A15 -> AV AMIN | C14: ='Pricing Piso Chile'!B15 -> 1000 L | D14: ='Pricing Piso Chile'!I15 -> 3000
B15: ='Pricing Piso Chile'!A16 -> AV AMIN SUGAR | C15: ='Pricing Piso Chile'!B16 -> 1 L | D15: ='Pricing Piso Chile'!I16 -> 9000
B16: ='Pricing Piso Chile'!A17 -> AV AMIN SUGAR | C16: ='Pricing Piso Chile'!B17 -> 5 L | D16: ='Pricing Piso Chile'!I17 -> 8000
... B142: ='Pricing Piso Chile'!A143 -> GREEN GUARDIAN MAX | C142: ='Pricing Piso Chile'!B143 -> 1000 L | D142: ='Pricing Piso Chile'!I143 -> 3800
