Workbook

Sheet Pricing Piso Peru
A1: TABLA DE PRECIOS PISO — PERÚ 2026 | AGROVECA GRUPO LATAM
A2: ⚙️ Celda B3 = margen objetivo (recalcula columnas E-K automáticamente). Celda azul = editable. Celda verde = precio propuesto por Gerencia. PRECIOS EN USD.
A3: MARGEN OBJETIVO → | B3: 0.47 | C3: ← Cambia este % y todo se recalcula
A5: PRODUCTO | B5: FORMATO | C5: COSTO FÁBRICA (PKG) USD | D5: TAMAÑO FMT | E5: COSTO USD/UNIDAD | F5: PRECIO PISO (CALCULADO) | G5: MARGEN CALC % | H5: PRECIO PROM REAL | I5: NUEVO PRECIO PISO PROPUESTO | J5: MARGEN PROPUESTO % | K5: GAP PROP. vs CALC % | L5: VAR $ (Prop - Real) | M5: CLASIF. PROPUESTO | N5: ORDEN FMT
A6: AV HUMIC ROOT | B6: 1 L | D6: 1 | E6: =IF(C6="","",C6/D6) | F6: =IF(E6="","",E6/(1-$B$3)) | G6: =$B$3 -> 0.47 | I6: 4.2 | J6: =IF(OR(I6="",E6=""),"",(I6-E6)/I6) | K6: =IF(OR(I6="",F6=""),"",(I6-F6)/F6) | L6: =IF(OR(I6="",H6=""),"",I6-H6) | M6: =IF(I6="","⚪ SIN PROPUESTA",IF(F6="","🟢 SOBRE PISO",IF(I6<F6*0.95,"🔴 BAJO PISO",IF(I6>F6*1.05,"🟢 SOBRE PISO","🟡 EN PISO")))) -> 🟢 SOBRE PISO | N6: 1
A7: AV HUMIC ROOT | B7: 20 L | C7: 32 | D7: 20 | E7: =IF(C7="","",C7/D7) -> 1.6 | F7: =IF(E7="","",E7/(1-$B$3)) -> 3.0188679 | G7: =$B$3 -> 0.47 | H7: 3.5 | I7: 3.5 | J7: =IF(OR(I7="",E7=""),"",(I7-E7)/I7) -> 0.54285714 | K7: =IF(OR(I7="",F7=""),"",(I7-F7)/F7) -> 0.159375 | L7: =IF(OR(I7="",H7=""),"",I7-H7) -> 0 | M7: =IF(I7="","⚪ SIN PROPUESTA",IF(F7="","🟢 SOBRE PISO",IF(I7<F7*0.95,"🔴 BAJO PISO",IF(I7>F7*1.05,"🟢 SOBRE PISO","🟡 EN PISO")))) -> 🟢 SOBRE PISO | N7: 3
A8: AV HUMIC ROOT | B8: 200 L | C8: 250 | D8: 200 | E8: =IF(C8="","",C8/D8) -> 1.25 | F8: =IF(E8="","",E8/(1-$B$3)) -> 2.3584906 | G8: =$B$3 -> 0.47 | I8: 3 | J8: =IF(OR(I8="",E8=""),"",(I8-E8)/I8) -> 0.58333333 | K8: =IF(OR(I8="",F8=""),"",(I8-F8)/F8) -> 0.272 | L8: =IF(OR(I8="",H8=""),"",I8-H8) | M8: =IF(I8="","⚪ SIN PROPUESTA",IF(F8="","🟢 SOBRE PISO",IF(I8<F8*0.95,"🔴 BAJO PISO",IF(I8>F8*1.05,"🟢 SOBRE PISO","🟡 EN PISO")))) -> 🟢 SOBRE PISO | N8: 4
A9: AV HUMIC ROOT | B9: 1000 L | C9: 1160 | D9: 1000 | E9: =IF(C9="","",C9/D9) -> 1.16 | F9: =IF(E9="","",E9/(1-$B$3)) -> 2.1886792 | G9: =$B$3 -> 0.47 | I9: 2.5 | J9: =IF(OR(I9="",E9=""),"",(I9-E9)/I9) -> 0.536 | K9: =IF(OR(I9="",F9=""),"",(I9-F9)/F9) -> 0.14224138 | L9: =IF(OR(I9="",H9=""),"",I9-H9) | M9: =IF(I9="","⚪ SIN PROPUESTA",IF(F9="","🟢 SOBRE PISO",IF(I9<F9*0.95,"🔴 BAJO PISO",IF(I9>F9*1.05,"🟢 SOBRE PISO","🟡 EN PISO")))) -> 🟢 SOBRE PISO | N9: 7
A10: AV MAX FULVIC 45% | B10: 1 L | D10: 1 | E10: =IF(C10="","",C10/D10) | F10: =IF(E10="","",E10/(1-$B$3)) | G10: =$B$3 -> 0.47 | I10: 4.2 | J10: =IF(OR(I10="",E10=""),"",(I10-E10)/I10) | K10: =IF(OR(I10="",F10=""),"",(I10-F10)/F10) | L10: =IF(OR(I10="",H10=""),"",I10-H10) | M10: =IF(I10="","⚪ SIN PROPUESTA",IF(F10="","🟢 SOBRE PISO",IF(I10<F10*0.95,"🔴 BAJO PISO",IF(I10>F10*1.05,"🟢 SOBRE PISO","🟡 EN PISO")))) -> 🟢 SOBRE PISO | N10: 1
A11: AV MAX FULVIC 45% | B11: 20 L | C11: 32 | D11: 20 | E11: =IF(C11="","",C11/D11) -> 1.6 | F11: =IF(E11="","",E11/(1-$B$3)) -> 3.0188679 | G11: =$B$3 -> 0.47 | H11: 2.8 | I11: 3 | J11: =IF(OR(I11="",E11=""),"",(I11-E11)/I11) -> 0.46666667 | K11: =IF(OR(I11="",F11=""),"",(I11-F11)/F11) -> -0.00625 | L11: =IF(OR(I11="",H11=""),"",I11-H11) -> 0.2 | M11: =IF(I11="","⚪ SIN PROPUESTA",IF(F11="","🟢 SOBRE PISO",IF(I11<F11*0.95,"🔴 BAJO PISO",IF(I11>F11*1.05,"🟢 SOBRE PISO","🟡 EN PISO")))) -> 🟡 EN PISO | N11: 3
A12: AV MAX FULVIC 45% | B12: 200 L | C12: 250 | D12: 200 | E12: =IF(C12="","",C12/D12) -> 1.25 | F12: =IF(E12="","",E12/(1-$B$3)) -> 2.3584906 | G12: =$B$3 -> 0.47 | I12: 2.5 | J12: =IF(OR(I12="",E12=""),"",(I12-E12)/I12) -> 0.5 | K12: =IF(OR(I12="",F12=""),"",(I12-F12)/F12) -> 0.06 | L12: =IF(OR(I12="",H12=""),"",I12-H12) | M12: =IF(I12="","⚪ SIN PROPUESTA",IF(F12="","🟢 SOBRE PISO",IF(I12<F12*0.95,"🔴 BAJO PISO",IF(I12>F12*1.05,"🟢 SOBRE PISO","🟡 EN PISO")))) -> 🟢 SOBRE PISO | N12: 4
A13: AV MAX FULVIC 45% | B13: 1000 L | C13: 1160 | D13: 1000 | E13: =IF(C13="","",C13/D13) -> 1.16 | F13: =IF(E13="","",E13/(1-$B$3)) -> 2.1886792 | G13: =$B$3 -> 0.47 | I13: 2.2 | J13: =IF(OR(I13="",E13=""),"",(I13-E13)/I13) -> 0.47272727 | K13: =IF(OR(I13="",F13=""),"",(I13-F13)/F13) -> 0.0051724138 | L13: =IF(OR(I13="",H13=""),"",I13-H13) | M13: =IF(I13="","⚪ SIN PROPUESTA",IF(F13="","🟢 SOBRE PISO",IF(I13<F13*0.95,"🔴 BAJO PISO",IF(I13>F13*1.05,"🟢 SOBRE PISO","🟡 EN PISO")))) -> 🟡 EN PISO | N13: 7
A14: AV AMIN | B14: 1 L | D14: 1 | E14: =IF(C14="","",C14/D14) | F14: =IF(E14="","",E14/(1-$B$3)) | G14: =$B$3 -> 0.47 | I14: 5 | J14: =IF(OR(I14="",E14=""),"",(I14-E14)/I14) | K14: =IF(OR(I14="",F14=""),"",(I14-F14)/F14) | L14: =IF(OR(I14="",H14=""),"",I14-H14) | M14: =IF(I14="","⚪ SIN PROPUESTA",IF(F14="","🟢 SOBRE PISO",IF(I14<F14*0.95,"🔴 BAJO PISO",IF(I14>F14*1.05,"🟢 SOBRE PISO","🟡 EN PISO")))) -> 🟢 SOBRE PISO | N14: 1
A15: AV AMIN | B15: 20 L | C15: 37 | D15: 20 | E15: =IF(C15="","",C15/D15) -> 1.85 | F15: =IF(E15="","",E15/(1-$B$3)) -> 3.490566 | G15: =$B$3 -> 0.47 | H15: 7.5 | I15: 4.2 | J15: =IF(OR(I15="",E15=""),"",(I15-E15)/I15) -> 0.55952381 | K15: =IF(OR(I15="",F15=""),"",(I15-F15)/F15) -> 0.20324324 | L15: =IF(OR(I15="",H15=""),"",I15-H15) -> -3.3 | M15: =IF(I15="","⚪ SIN PROPUESTA",IF(F15="","🟢 SOBRE PISO",IF(I15<F15*0.95,"🔴 BAJO PISO",IF(I15>F15*1.05,"🟢 SOBRE PISO","🟡 EN PISO")))) -> 🟢 SOBRE PISO | N15: 3
A16: AV AMIN | B16: 200 L | C16: 255 | D16: 200 | E16: =IF(C16="","",C16/D16) -> 1.275 | F16: =IF(E16="","",E16/(1-$B$3)) -> 2.4056604 | G16: =$B$3 -> 0.47 | I16: 3.5 | J16: =IF(OR(I16="",E16=""),"",(I16-E16)/I16) -> 0.63571429 | K16: =IF(OR(I16="",F16=""),"",(I16-F16)/F16) -> 0.45490196 | L16: =IF(OR(I16="",H16=""),"",I16-H16) | M16: =IF(I16="","⚪ SIN PROPUESTA",IF(F16="","🟢 SOBRE PISO",IF(I16<F16*0.95,"🔴 BAJO PISO",IF(I16>F16*1.05,"🟢 SOBRE PISO","🟡 EN PISO")))) -> 🟢 SOBRE PISO | N16: 4
A17: AV AMIN | B17: 1000 L | C17: 1492 | D17: 1000 | E17: =IF(C17="","",C17/D17) -> 1.492 | F17: =IF(E17="","",E17/(1-$B$3)) -> 2.8150943 | G17: =$B$3 -> 0.47 | I17: 3 | J17: =IF(OR(I17="",E17=""),"",(I17-E17)/I17) -> 0.50266667 | K17: =IF(OR(I17="",F17=""),"",(I17-F17)/F17) -> 0.065683646 | L17: =IF(OR(I17="",H17=""),"",I17-H17) | M17: =IF(I17="","⚪ SIN PROPUESTA",IF(F17="","🟢 SOBRE PISO",IF(I17<F17*0.95,"🔴 BAJO PISO",IF(I17>F17*1.05,"🟢 SOBRE PISO","🟡 EN PISO")))) -> 🟢 SOBRE PISO | N17: 7
A18: AV AMIN SUGAR | B18: 1 L | D18: 1 | E18: =IF(C18="","",C18/D18) | F18: =IF(E18="","",E18/(1-$B$3)) | G18: =$B$3 -> 0.47 | I18: 8 | J18: =IF(OR(I18="",E18=""),"",(I18-E18)/I18) | K18: =IF(OR(I18="",F18=""),"",(I18-F18)/F18) | L18: =IF(OR(I18="",H18=""),"",I18-H18) | M18: =IF(I18="","⚪ SIN PROPUESTA",IF(F18="","🟢 SOBRE PISO",IF(I18<F18*0.95,"🔴 BAJO PISO",IF(I18>F18*1.05,"🟢 SOBRE PISO","🟡 EN PISO")))) -> 🟢 SOBRE PISO | N18: 1
A19: AV AMIN SUGAR | B19: 20 L | C19: 36 | D19: 20 | E19: =IF(C19="","",C19/D19) -> 1.8 | F19: =IF(E19="","",E19/(1-$B$3)) -> 3.3962264 | G19: =$B$3 -> 0.47 | I19: 7.5 | J19: =IF(OR(I19="",E19=""),"",(I19-E19)/I19) -> 0.76 | K19: =IF(OR(I19="",F19=""),"",(I19-F19)/F19) -> 1.2083333 | L19: =IF(OR(I19="",H19=""),"",I19-H19) | M19: =IF(I19="","⚪ SIN PROPUESTA",IF(F19="","🟢 SOBRE PISO",IF(I19<F19*0.95,"🔴 BAJO PISO",IF(I19>F19*1.05,"🟢 SOBRE PISO","🟡 EN PISO")))) -> 🟢 SOBRE PISO | N19: 3
A20: AV AMIN SUGAR | B20: 200 L | C20: 240 | D20: 200 | E20: =IF(C20="","",C20/D20) -> 1.2 | F20: =IF(E20="","",E20/(1-$B$3)) -> 2.2641509 | G20: =$B$3 -> 0.47 | I20: 6 | J20: =IF(OR(I20="",E20=""),"",(I20-E20)/I20) -> 0.8 | K20: =IF(OR(I20="",F20=""),"",(I20-F20)/F20) -> 1.65 | L20: =IF(OR(I20="",H20=""),"",I20-H20) | M20: =IF(I20="","⚪ SIN PROPUESTA",IF(F20="","🟢 SOBRE PISO",IF(I20<F20*0.95,"🔴 BAJO PISO",IF(I20>F20*1.05,"🟢 SOBRE PISO","🟡 EN PISO")))) -> 🟢 SOBRE PISO | N20: 4
A21: AV AMIN SUGAR | B21: 1000 L | C21: 1412 | D21: 1000 | E21: =IF(C21="","",C21/D21) -> 1.412 | F21: =IF(E21="","",E21/(1-$B$3)) -> 2.6641509 | G21: =$B$3 -> 0.47 | I21: 5 | J21: =IF(OR(I21="",E21=""),"",(I21-E21)/I21) -> 0.7176 | K21: =IF(OR(I21="",F21=""),"",(I21-F21)/F21) -> 0.87677054 | L21: =IF(OR(I21="",H21=""),"",I21-H21) | M21: =IF(I21="","⚪ SIN PROPUESTA",IF(F21="","🟢 SOBRE PISO",IF(I21<F21*0.95,"🔴 BAJO PISO",IF(I21>F21*1.05,"🟢 SOBRE PISO","🟡 EN PISO")))) -> 🟢 SOBRE PISO | N21: 7
A22: AV ROOT MAX | B22: 1 L | D22: 1 | E22: =IF(C22="","",C22/D22) | F22: =IF(E22="","",E22/(1-$B$3)) | G22: =$B$3 -> 0.47 | I22: 15 | J22: =IF(OR(I22="",E22=""),"",(I22-E22)/I22) | K22: =IF(OR(I22="",F22=""),"",(I22-F22)/F22) | L22: =IF(OR(I22="",H22=""),"",I22-H22) | M22: =IF(I22="","⚪ SIN PROPUESTA",IF(F22="","🟢 SOBRE PISO",IF(I22<F22*0.95,"🔴 BAJO PISO",IF(I22>F22*1.05,"🟢 SOBRE PISO","🟡 EN PISO")))) -> 🟢 SOBRE PISO | N22: 1
A23: AV ROOT MAX | B23: 20 L | C23: 36 | D23: 20 | E23: =IF(C23="","",C23/D23) -> 1.8 | F23: =IF(E23="","",E23/(1-$B$3)) -> 3.3962264 | G23: =$B$3 -> 0.47 | H23: 13.86 | I23: 13.8 | J23: =IF(OR(I23="",E23=""),"",(I23-E23)/I23) -> 0.86956522 | K23: =IF(OR(I23="",F23=""),"",(I23-F23)/F23) -> 3.0633333 | L23: =IF(OR(I23="",H23=""),"",I23-H23) -> -0.06 | M23: =IF(I23="","⚪ SIN PROPUESTA",IF(F23="","🟢 SOBRE PISO",IF(I23<F23*0.95,"🔴 BAJO PISO",IF(I23>F23*1.05,"🟢 SOBRE PISO","🟡 EN PISO")))) -> 🟢 SOBRE PISO | N23: 3
A24: AV ROOT MAX | B24: 200 L | C24: 250 | D24: 200 | E24: =IF(C24="","",C24/D24) -> 1.25 | F24: =IF(E24="","",E24/(1-$B$3)) -> 2.3584906 | G24: =$B$3 -> 0.47 | I24: 12 | J24: =IF(OR(I24="",E24=""),"",(I24-E24)/I24) -> 0.89583333 | K24: =IF(OR(I24="",F24=""),"",(I24-F24)/F24) -> 4.088 | L24: =IF(OR(I24="",H24=""),"",I24-H24) | M24: =IF(I24="","⚪ SIN PROPUESTA",IF(F24="","🟢 SOBRE PISO",IF(I24<F24*0.95,"🔴 BAJO PISO",IF(I24>F24*1.05,"🟢 SOBRE PISO","🟡 EN PISO")))) -> 🟢 SOBRE PISO | N24: 4
A25: AV ROOT MAX | B25: 1000 L | C25: 1170 | D25: 1000 | E25: =IF(C25="","",C25/D25) -> 1.17 | F25: =IF(E25="","",E25/(1-$B$3)) -> 2.2075472 | G25: =$B$3 -> 0.47 | I25: 11 | J25: =IF(OR(I25="",E25=""),"",(I25-E25)/I25) -> 0.89363636 | K25: =IF(OR(I25="",F25=""),"",(I25-F25)/F25) -> 3.982906 | L25: =IF(OR(I25="",H25=""),"",I25-H25) | M25: =IF(I25="","⚪ SIN PROPUESTA",IF(F25="","🟢 SOBRE PISO",IF(I25<F25*0.95,"🔴 BAJO PISO",IF(I25>F25*1.05,"🟢 SOBRE PISO","🟡 EN PISO")))) -> 🟢 SOBRE PISO | N25: 7
A26: AV ALGAP 30 | B26: 1 L | D26: 1 | E26: =IF(C26="","",C26/D26) | F26: =IF(E26="","",E26/(1-$B$3)) | G26: =$B$3 -> 0.47 | I26: 11 | J26: =IF(OR(I26="",E26=""),"",(I26-E26)/I26) | K26: =IF(OR(I26="",F26=""),"",(I26-F26)/F26) | L26: =IF(OR(I26="",H26=""),"",I26-H26) | M26: =IF(I26="","⚪ SIN PROPUESTA",IF(F26="","🟢 SOBRE PISO",IF(I26<F26*0.95,"🔴 BAJO PISO",IF(I26>F26*1.05,"🟢 SOBRE PISO","🟡 EN PISO")))) -> 🟢 SOBRE PISO | N26: 1
A27: AV ALGAP 30 | B27: 20 L | C27: 40 | D27: 20 | E27: =IF(C27="","",C27/D27) -> 2 | F27: =IF(E27="","",E27/(1-$B$3)) -> 3.7735849 | G27: =$B$3 -> 0.47 | H27: 10.4 | I27: 10 | J27: =IF(OR(I27="",E27=""),"",(I27-E27)/I27) -> 0.8 | K27: =IF(OR(I27="",F27=""),"",(I27-F27)/F27) -> 1.65 | L27: =IF(OR(I27="",H27=""),"",I27-H27) -> -0.4 | M27: =IF(I27="","⚪ SIN PROPUESTA",IF(F27="","🟢 SOBRE PISO",IF(I27<F27*0.95,"🔴 BAJO PISO",IF(I27>F27*1.05,"🟢 SOBRE PISO","🟡 EN PISO")))) -> 🟢 SOBRE PISO | N27: 3
A28: AV ALGAP 30 | B28: 200 L | C28: 340 | D28: 200 | E28: =IF(C28="","",C28/D28) -> 1.7 | F28: =IF(E28="","",E28/(1-$B$3)) -> 3.2075472 | G28: =$B$3 -> 0.47 | I28: 8 | J28: =IF(OR(I28="",E28=""),"",(I28-E28)/I28) -> 0.7875 | K28: =IF(OR(I28="",F28=""),"",(I28-F28)/F28) -> 1.4941176 | L28: =IF(OR(I28="",H28=""),"",I28-H28) | M28: =IF(I28="","⚪ SIN PROPUESTA",IF(F28="","🟢 SOBRE PISO",IF(I28<F28*0.95,"🔴 BAJO PISO",IF(I28>F28*1.05,"🟢 SOBRE PISO","🟡 EN PISO")))) -> 🟢 SOBRE PISO | N28: 4
A29: AV ALGAP 30 | B29: 1000 L | C29: 1560 | D29: 1000 | E29: =IF(C29="","",C29/D29) -> 1.56 | F29: =IF(E29="","",E29/(1-$B$3)) -> 2.9433962 | G29: =$B$3 -> 0.47 | I29: 5.8 | J29: =IF(OR(I29="",E29=""),"",(I29-E29)/I29) -> 0.73103448 | K29: =IF(OR(I29="",F29=""),"",(I29-F29)/F29) -> 0.97051282 | L29: =IF(OR(I29="",H29=""),"",I29-H29) | M29: =IF(I29="","⚪ SIN PROPUESTA",IF(F29="","🟢 SOBRE PISO",IF(I29<F29*0.95,"🔴 BAJO PISO",IF(I29>F29*1.05,"🟢 SOBRE PISO","🟡 EN PISO")))) -> 🟢 SOBRE PISO | N29: 7
A30: AV SILFORTE | B30: 1 L | D30: 1 | E30: =IF(C30="","",C30/D30) | F30: =IF(E30="","",E30/(1-$B$3)) | G30: =$B$3 -> 0.47 | I30: 14 | J30: =IF(OR(I30="",E30=""),"",(I30-E30)/I30) | K30: =IF(OR(I30="",F30=""),"",(I30-F30)/F30) | L30: =IF(OR(I30="",H30=""),"",I30-H30) | M30: =IF(I30="","⚪ SIN PROPUESTA",IF(F30="","🟢 SOBRE PISO",IF(I30<F30*0.95,"🔴 BAJO PISO",IF(I30>F30*1.05,"🟢 SOBRE PISO","🟡 EN PISO")))) -> 🟢 SOBRE PISO | N30: 1
A31: AV SILFORTE | B31: 20 L | C31: 48 | D31: 20 | E31: =IF(C31="","",C31/D31) -> 2.4 | F31: =IF(E31="","",E31/(1-$B$3)) -> 4.5283019 | G31: =$B$3 -> 0.47 | H31: 12.05 | I31: 13 | J31: =IF(OR(I31="",E31=""),"",(I31-E31)/I31) -> 0.81538462 | K31: =IF(OR(I31="",F31=""),"",(I31-F31)/F31) -> 1.8708333 | L31: =IF(OR(I31="",H31=""),"",I31-H31) -> 0.95 | M31: =IF(I31="","⚪ SIN PROPUESTA",IF(F31="","🟢 SOBRE PISO",IF(I31<F31*0.95,"🔴 BAJO PISO",IF(I31>F31*1.05,"🟢 SOBRE PISO","🟡 EN PISO")))) -> 🟢 SOBRE PISO | N31: 3
A32: AV SILFORTE | B32: 200 L | C32: 430 | D32: 200 | E32: =IF(C32="","",C32/D32) -> 2.15 | F32: =IF(E32="","",E32/(1-$B$3)) -> 4.0566038 | G32: =$B$3 -> 0.47 | I32: 12 | J32: =IF(OR(I32="",E32=""),"",(I32-E32)/I32) -> 0.82083333 | K32: =IF(OR(I32="",F32=""),"",(I32-F32)/F32) -> 1.9581395 | L32: =IF(OR(I32="",H32=""),"",I32-H32) | M32: =IF(I32="","⚪ SIN PROPUESTA",IF(F32="","🟢 SOBRE PISO",IF(I32<F32*0.95,"🔴 BAJO PISO",IF(I32>F32*1.05,"🟢 SOBRE PISO","🟡 EN PISO")))) -> 🟢 SOBRE PISO | N32: 4
A33: AV SILFORTE | B33: 1000 L | C33: 1990 | D33: 1000 | E33: =IF(C33="","",C33/D33) -> 1.99 | F33: =IF(E33="","",E33/(1-$B$3)) -> 3.754717 | G33: =$B$3 -> 0.47 | I33: 10 | J33: =IF(OR(I33="",E33=""),"",(I33-E33)/I33) -> 0.801 | K33: =IF(OR(I33="",F33=""),"",(I33-F33)/F33) -> 1.6633166 | L33: =IF(OR(I33="",H33=""),"",I33-H33) | M33: =IF(I33="","⚪ SIN PROPUESTA",IF(F33="","🟢 SOBRE PISO",IF(I33<F33*0.95,"🔴 BAJO PISO",IF(I33>F33*1.05,"🟢 SOBRE PISO","🟡 EN PISO")))) -> 🟢 SOBRE PISO | N33: 7
A34: GREEN GUARDIAN MAX | B34: 1 L | D34: 1 | E34: =IF(C34="","",C34/D34) | F34: =IF(E34="","",E34/(1-$B$3)) | G34: =$B$3 -> 0.47 | I34: 5 | J34: =IF(OR(I34="",E34=""),"",(I34-E34)/I34) | K34: =IF(OR(I34="",F34=""),"",(I34-F34)/F34) | L34: =IF(OR(I34="",H34=""),"",I34-H34) | M34: =IF(I34="","⚪ SIN PROPUESTA",IF(F34="","🟢 SOBRE PISO",IF(I34<F34*0.95,"🔴 BAJO PISO",IF(I34>F34*1.05,"🟢 SOBRE PISO","🟡 EN PISO")))) -> 🟢 SOBRE PISO | N34: 1
A35: GREEN GUARDIAN MAX | B35: 20 L | C35: 44 | D35: 20 | E35: =IF(C35="","",C35/D35) -> 2.2 | F35: =IF(E35="","",E35/(1-$B$3)) -> 4.1509434 | G35: =$B$3 -> 0.47 | I35: 4.5 | J35: =IF(OR(I35="",E35=""),"",(I35-E35)/I35) -> 0.51111111 | K35: =IF(OR(I35="",F35=""),"",(I35-F35)/F35) -> 0.084090909 | L35: =IF(OR(I35="",H35=""),"",I35-H35) | M35: =IF(I35="","⚪ SIN PROPUESTA",IF(F35="","🟢 SOBRE PISO",IF(I35<F35*0.95,"🔴 BAJO PISO",IF(I35>F35*1.05,"🟢 SOBRE PISO","🟡 EN PISO")))) -> 🟢 SOBRE PISO | N35: 3
A36: GREEN GUARDIAN MAX | B36: 200 L | C36: 380 | D36: 200 | E36: =IF(C36="","",C36/D36) -> 1.9 | F36: =IF(E36="","",E36/(1-$B$3)) -> 3.5849057 | G36: =$B$3 -> 0.47 | I36: 4 | J36: =IF(OR(I36="",E36=""),"",(I36-E36)/I36) -> 0.525 | K36: =IF(OR(I36="",F36=""),"",(I36-F36)/F36) -> 0.11578947 | L36: =IF(OR(I36="",H36=""),"",I36-H36) | M36: =IF(I36="","⚪ SIN PROPUESTA",IF(F36="","🟢 SOBRE PISO",IF(I36<F36*0.95,"🔴 BAJO PISO",IF(I36>F36*1.05,"🟢 SOBRE PISO","🟡 EN PISO")))) -> 🟢 SOBRE PISO | N36: 4
A37: GREEN GUARDIAN MAX | B37: 1000 L | C37: 1820 | D37: 1000 | E37: =IF(C37="","",C37/D37) -> 1.82 | F37: =IF(E37="","",E37/(1-$B$3)) -> 3.4339623 | G37: =$B$3 -> 0.47 | I37: 3.5 | J37: =IF(OR(I37="",E37=""),"",(I37-E37)/I37) -> 0.48 | K37: =IF(OR(I37="",F37=""),"",(I37-F37)/F37) -> 0.019230769 | L37: =IF(OR(I37="",H37=""),"",I37-H37) | M37: =IF(I37="","⚪ SIN PROPUESTA",IF(F37="","🟢 SOBRE PISO",IF(I37<F37*0.95,"🔴 BAJO PISO",IF(I37>F37*1.05,"🟢 SOBRE PISO","🟡 EN PISO")))) -> 🟡 EN PISO | N37: 7
A38: AV15 40-20 | B38: 1 L | D38: 1 | E38: =IF(C38="","",C38/D38) | F38: =IF(E38="","",E38/(1-$B$3)) | G38: =$B$3 -> 0.47 | I38: 5 | J38: =IF(OR(I38="",E38=""),"",(I38-E38)/I38) | K38: =IF(OR(I38="",F38=""),"",(I38-F38)/F38) | L38: =IF(OR(I38="",H38=""),"",I38-H38) | M38: =IF(I38="","⚪ SIN PROPUESTA",IF(F38="","🟢 SOBRE PISO",IF(I38<F38*0.95,"🔴 BAJO PISO",IF(I38>F38*1.05,"🟢 SOBRE PISO","🟡 EN PISO")))) -> 🟢 SOBRE PISO | N38: 1
A39: AV15 40-20 | B39: 20 L | C39: 38 | D39: 20 | E39: =IF(C39="","",C39/D39) -> 1.9 | F39: =IF(E39="","",E39/(1-$B$3)) -> 3.5849057 | G39: =$B$3 -> 0.47 | I39: 4 | J39: =IF(OR(I39="",E39=""),"",(I39-E39)/I39) -> 0.525 | K39: =IF(OR(I39="",F39=""),"",(I39-F39)/F39) -> 0.11578947 | L39: =IF(OR(I39="",H39=""),"",I39-H39) | M39: =IF(I39="","⚪ SIN PROPUESTA",IF(F39="","🟢 SOBRE PISO",IF(I39<F39*0.95,"🔴 BAJO PISO",IF(I39>F39*1.05,"🟢 SOBRE PISO","🟡 EN PISO")))) -> 🟢 SOBRE PISO | N39: 3
A40: AV15 40-20 | B40: 200 L | C40: 330 | D40: 200 | E40: =IF(C40="","",C40/D40) -> 1.65 | F40: =IF(E40="","",E40/(1-$B$3)) -> 3.1132075 | G40: =$B$3 -> 0.47 | I40: 3 | J40: =IF(OR(I40="",E40=""),"",(I40-E40)/I40) -> 0.45 | K40: =IF(OR(I40="",F40=""),"",(I40-F40)/F40) -> -0.036363636 | L40: =IF(OR(I40="",H40=""),"",I40-H40) | M40: =IF(I40="","⚪ SIN PROPUESTA",IF(F40="","🟢 SOBRE PISO",IF(I40<F40*0.95,"🔴 BAJO PISO",IF(I40>F40*1.05,"🟢 SOBRE PISO","🟡 EN PISO")))) -> 🟡 EN PISO | N40: 4
A41: AV15 40-20 | B41: 1000 L | C41: 1540 | D41: 1000 | E41: =IF(C41="","",C41/D41) -> 1.54 | F41: =IF(E41="","",E41/(1-$B$3)) -> 2.9056604 | G41: =$B$3 -> 0.47 | I41: 2.8 | J41: =IF(OR(I41="",E41=""),"",(I41-E41)/I41) -> 0.45 | K41: =IF(OR(I41="",F41=""),"",(I41-F41)/F41) -> -0.036363636 | L41: =IF(OR(I41="",H41=""),"",I41-H41) | M41: =IF(I41="","⚪ SIN PROPUESTA",IF(F41="","🟢 SOBRE PISO",IF(I41<F41*0.95,"🔴 BAJO PISO",IF(I41>F41*1.05,"🟢 SOBRE PISO","🟡 EN PISO")))) -> 🟡 EN PISO | N41: 7
...

Sheet precios piso peru 
B1: LISTA DE PRECIOS PISO — FUERZA COMERCIAL PERÚ 2026
B2: AGROVECA PERÚ S.A.C. | Precios mínimos de venta (USD/Unidad) | Vigencia: Abril 2026 | Aprobado: Gerencia General
B3: ⚠️ Ninguna venta puede realizarse por debajo de estos precios sin autorización escrita de Gerencia General.
B4: PRODUCTO | C4: FORMATO | D4: Precio Piso AV (USD/Unidad) | E4: Precio Piso AV (USD/Unidad)
B5: ='Pricing Piso Peru'!A6 -> AV HUMIC ROOT | C5: ='Pricing Piso Peru'!B6 -> 1 L | D5: ='Pricing Piso Peru'!I6 -> 4.2 | E5: ='Pricing Piso Peru'!M6 -> 🟢 SOBRE PISO
B6: ='Pricing Piso Peru'!A7 -> AV HUMIC ROOT | C6: ='Pricing Piso Peru'!B7 -> 20 L | D6: ='Pricing Piso Peru'!I7 -> 3.5 | E6: ='Pricing Piso Peru'!M7 -> 🟢 SOBRE PISO
B7: ='Pricing Piso Peru'!A8 -> AV HUMIC ROOT | C7: ='Pricing Piso Peru'!B8 -> 200 L | D7: ='Pricing Piso Peru'!I8 -> 3 | E7: ='Pricing Piso Peru'!M8 -> 🟢 SOBRE PISO
B8: ='Pricing Piso Peru'!A9 -> AV HUMIC ROOT | C8: ='Pricing Piso Peru'!B9 -> 1000 L | D8: ='Pricing Piso Peru'!I9 -> 2.5 | E8: ='Pricing Piso Peru'!M9 -> 🟢 SOBRE PISO
B9: ='Pricing Piso Peru'!A10 -> AV MAX FULVIC 45% | C9: ='Pricing Piso Peru'!B10 -> 1 L | D9: ='Pricing Piso Peru'!I10 -> 4.2 | E9: ='Pricing Piso Peru'!M10 -> 🟢 SOBRE PISO
B10: ='Pricing Piso Peru'!A11 -> AV MAX FULVIC 45% | C10: ='Pricing Piso Peru'!B11 -> 20 L | D10: ='Pricing Piso Peru'!I11 -> 3 | E10: ='Pricing Piso Peru'!M11 -> 🟡 EN PISO
B11: ='Pricing Piso Peru'!A12 -> AV MAX FULVIC 45% | C11: ='Pricing Piso Peru'!B12 -> 200 L | D11: ='Pricing Piso Peru'!I12 -> 2.5 | E11: ='Pricing Piso Peru'!M12 -> 🟢 SOBRE PISO
B12: ='Pricing Piso Peru'!A13 -> AV MAX FULVIC 45% | C12: ='Pricing Piso Peru'!B13 -> 1000 L | D12: ='Pricing Piso Peru'!I13 -> 2.2 | E12: ='Pricing Piso Peru'!M13 -> 🟡 EN PISO
B13: ='Pricing Piso Peru'!A14 -> AV AMIN | C13: ='Pricing Piso Peru'!B14 -> 1 L | D13: ='Pricing Piso Peru'!I14 -> 5 | E13: ='Pricing Piso Peru'!M14 -> 🟢 SOBRE PISO
B14: ='Pricing Piso Peru'!A15 -> AV AMIN | C14: ='Pricing Piso Peru'!B15 -> 20 L | D14: ='Pricing Piso Peru'!I15 -> 4.2 | E14: ='Pricing Piso Peru'!M15 -> 🟢 SOBRE PISO
B15: ='Pricing Piso Peru'!A16 -> AV AMIN | C15: ='Pricing Piso Peru'!B16 -> 200 L | D15: ='Pricing Piso Peru'!I16 -> 3.5 | E15: ='Pricing Piso Peru'!M16 -> 🟢 SOBRE PISO
B16: ='Pricing Piso Peru'!A17 -> AV AMIN | C16: ='Pricing Piso Peru'!B17 -> 1000 L | D16: ='Pricing Piso Peru'!I17 -> 3 | E16: ='Pricing Piso Peru'!M17 -> 🟢 SOBRE PISO
... B108: ='Pricing Piso Peru'!A109 -> AV BIOSOLARIS | C108: ='Pricing Piso Peru'!B109 -> 1000 L | D108: ='Pricing Piso Peru'!I109 -> 14 | E108: ='Pricing Piso Peru'!M109 -> 🟢 SOBRE PISO
